Workbook

Sheet Read Me
A1: Modulark Lighting — Cost and Timeline for Filings and Certifications
A2: Modulark Tech Labs Pvt Ltd · lighting hardware division · prepared 22 September 2026
A4: NOT LEGAL ADVICE
A5: Working document to brief a registered patent agent and a company secretary. Every material figure must be
A6: confirmed with them before it is relied on or committed to.
A8: SOURCING LIMITATION — READ THIS BEFORE USING ANY NUMBER
A9: The research behind this file was produced in an environment whose network proxy blocked every primary legal
A10: source: indiacode.nic.in (bare Acts), indiankanoon.org (case law), ipindia.gov.in, bis.gov.in, crsbis.in,
A11: meity.gov.in, egazette.gov.in, cpcb.nic.in, rbi.org.in and the WIPO fee tables. Nothing was read in original
A12: text. Figures come from search-engine extracts of those sources plus law-firm and compliance commentary.
A13: Where no citable figure could be obtained, the cell is left blank and marked NOT SOURCED. No number in this
A14: workbook has been invented to fill a gap.
... A35: Action Plan Priority-ordered tasks with owner and status columns for you to fill in.

Sheet Cost and Timeline
A1: Phase | B1: Category | C1: Item | D1: Official fee low (reduced slab) | E1: Official fee high (reduced slab) | F1: Official fee (large entity) | G1: Professional fee low | H1: Professional fee high | I1: Est. total low | J1: Est. total high | K1: Timing / elapsed | L1: Deadline trigger | M1: Sourcing | N1: Notes | O1: In headline total?
A2: 1 | B2: Patent | C2: Provisional specification (Form 1, <=30pp, <=10 claims) | D2: 1600 | E2: 1600 | F2: 8000 | G2: 25000 | H2: 60000 | I2: =IF(COUNT(D2,G2)=0,"",SUM(D2,G2)) | J2: =IF(COUNT(E2,H2)=0,"",SUM(E2,H2)) | K2: Days to file | L2: File before ANY disclosure | M2: Sourced | N2: Commodity market is Rs 6k-12k. That buys a thin provisional that will not hold the priority date for this invention. | O2: Yes
A3: 2 | B3: Patent | C3: Complete specification | D3: 1600 | E3: 1600 | F3: 8000 | G3: 60000 | H3: 120000 | I3: =IF(COUNT(D3,G3)=0,"",SUM(D3,G3)) | J3: =IF(COUNT(E3,H3)=0,"",SUM(E3,H3)) | K3: Within 12 months of provisional | L3: ABSOLUTE - provisional + 12 months | M3: Sourced | N3: Includes drawings. No extension, no condonation, no post-dating. | O3: Yes
A4: 2 | B4: Patent | C4: Request for Examination (Form 18) | D4: 4000 | E4: 4000 | F4: 20000 | I4: =IF(COUNT(D4,G4)=0,"",SUM(D4,G4)) | J4: =IF(COUNT(E4,H4)=0,"",SUM(E4,H4)) | K4: Due by 31 months from priority | L4: Priority + 31 months | M4: Sourced | N4: Cut from 48 to 31 months by the Patents (Amendment) Rules 2024 for filings on/after 15 Mar 2024. | O4: Yes
A5: 2 | B5: Patent | C5: Expedited Examination (Form 18A) | D5: 8000 | E5: 8000 | F5: 60000 | I5: =IF(COUNT(D5,G5)=0,"",SUM(D5,G5)) | J5: =IF(COUNT(E5,H5)=0,"",SUM(E5,H5)) | K5: FER in 1-3 months vs 12-24 ordinary | L5: Optional, recommended | M5: Sourced | N5: Available to DPIIT startups. Converts a 3-5 year grant into 1-2 years. | O5: Yes
A6: 2 | B6: Patent | C6: Early Publication (Form 9) | D6: 2500 | E6: 2500 | F6: 12500 | I6: =IF(COUNT(D6,G6)=0,"",SUM(D6,G6)) | J6: =IF(COUNT(E6,H6)=0,"",SUM(E6,H6)) | K6: Publishes in ~1 month vs 18 | L6: Optional, recommended | M6: Sourced | N6: Pair with Form 18A. Cost delta of both is roughly Rs 6,500. | O6: Yes
A7: 2 | B7: Patent | C7: First Examination Report response | G7: 25000 | H7: 60000 | I7: =IF(COUNT(D7,G7)=0,"",SUM(D7,G7)) | J7: =IF(COUNT(E7,H7)=0,"",SUM(E7,H7)) | K7: 6 months to respond, +3 extendable | L7: On receipt of FER | M7: Sourced | N7: Expect a Section 3(k) objection cycle. | O7: Yes
A8: 2 | B8: Patent | C8: Extension of RFE-type deadlines (2024 Rules) | F8: 50000 | I8: =IF(COUNT(D8,G8)=0,"",SUM(D8,G8)) | J8: =IF(COUNT(E8,H8)=0,"",SUM(E8,H8)) | K8: Per month | L8: Avoid | M8: Sourced | N8: Rs 50,000 PER MONTH. Treat deadlines as absolute. [Excluded from headline total: Penalty to avoid, not a planned spend] | O8: No
A9: 2 | B9: Patent | C9: Foreign Filing Licence (Form 25) | I9: =IF(COUNT(D9,G9)=0,"",SUM(D9,G9)) | J9: =IF(COUNT(E9,H9)=0,"",SUM(E9,H9)) | K9: ~3 weeks reported, unverified | L9: Before any foreign filing | M9: NOT SOURCED | N9: Alternative: file in India first and wait 6 weeks. Section 39 breach is CRIMINAL - s.118, up to 2 years. | O9: Yes
A10: 3 | B10: Patent | C10: PCT international filing fee | I10: =IF(COUNT(D10,G10)=0,"",SUM(D10,G10)) | J10: =IF(COUNT(E10,H10)=0,"",SUM(E10,H10)) | K10: By 12 months from priority | L10: Provisional + 12 months | M10: CONFLICT | N10: USD 1,471 vs USD 1,667 from the same publisher. Set in CHF so it moves. The WIPO 90% reduction is for natural persons resident in India ONLY - not companies, startups or MSMEs. | O10: Yes
A11: 3 | B11: Patent | C11: PCT search fee - IPO as ISA | D11: 2500 | E11: 2500 | F11: 10000 | I11: =IF(COUNT(D11,G11)=0,"",SUM(D11,G11)) | J11: =IF(COUNT(E11,H11)=0,"",SUM(E11,H11)) | K11: With PCT filing | L11: - | M11: Sourced | N11: Cheapest option but weaker search quality in control-systems art. | O11: Yes
A12: 3 | B12: Patent | C12: PCT search fee - EPO as ISA | I12: =IF(COUNT(D12,G12)=0,"",SUM(D12,G12)) | J12: =IF(COUNT(E12,H12)=0,"",SUM(E12,H12)) | K12: With PCT filing | L12: - | M12: NOT SOURCED | N12: Order of a thousand-plus euros. Worth paying for: your fight is inventive step over dense Signify/Lutron art. | O12: Yes
A13: 3 | B13: Patent | C13: PCT transmittal fee (IPO as Receiving Office) | I13: =IF(COUNT(D13,G13)=0,"",SUM(D13,G13)) | J13: =IF(COUNT(E13,H13)=0,"",SUM(E13,H13)) | K13: With PCT filing | L13: - | M13: NOT SOURCED | N13: ~Rs 3,200 / Rs 16,000 commonly cited, unconfirmed. | O13: Yes
A14: 3 | B14: Patent | C14: PCT national phase entry, India | I14: =IF(COUNT(D14,G14)=0,"",SUM(D14,G14)) | J14: =IF(COUNT(E14,H14)=0,"",SUM(E14,H14)) | K14: 31 months | L14: Same date as RFE - docket as one | M14: Sourced | N14: The 2024 Rules merged these two deadlines. | O14: Yes
A15: 2 | B15: Patent | C15: Assignment recordal (Form 16) | D15: 1600 | E15: 8000 | F15: 8000 | G15: 10000 | H15: 30000 | I15: =IF(COUNT(D15,G15)=0,"",SUM(D15,G15)) | J15: =IF(COUNT(E15,H15)=0,"",SUM(E15,H15)) | K15: - | L15: On any entity transfer | M15: Sourced | N15: Plus notarisation Rs 2,000-5,000. Avoid by filing in the right entity first time. | O15: Yes
A16: 1 | B16: Patent | C16: Form 6 - pre-grant change of applicant | I16: =IF(COUNT(D16,G16)=0,"",SUM(D16,G16)) | J16: =IF(COUNT(E16,H16)=0,"",SUM(E16,H16)) | K16: - | L16: - | M16: NOT SOURCED | N16: Not found in any source. Far cheaper and cleaner than post-grant Form 16. Check the First Schedule. | O16: Yes
A17: 1 | B17: Design | C17: Design registration, per design | D17: 1000 | E17: 1000 | F17: 4000 | G17: 5000 | H17: 15000 | I17: =IF(COUNT(D17,G17)=0,"",SUM(D17,G17)) | J17: =IF(COUNT(E17,H17)=0,"",SUM(E17,H17)) | K17: Registration 3-10 months | L17: File BEFORE any disclosure | M17: CONFLICT | N17: One source self-inconsistently says Rs 2,000 for small entity. Optional search Rs 2,000-5,000. India has NO general grace period for designs. | O17: Yes
A18: 1 | B18: Design | C18: Design, realistic all-in per design | G18: 8000 | H18: 25000 | I18: =IF(COUNT(D18,G18)=0,"",SUM(D18,G18)) | J18: =IF(COUNT(E18,H18)=0,"",SUM(E18,H18)) | K18: Term 10 yrs + 5 = 15 max | L18: - | M18: Sourced | N18: File the assembled module, light head and wall disc as separate designs in Locarno 26-05. [Excluded from headline total: Roll-up of rows already counted — would double count] | O18: No
A19: 2 | B19: Design | C19: Design renewal (Form 3) | D19: 2000 | E19: 2000 | F19: 8000 | I19: =IF(COUNT(D19,G19)=0,"",SUM(D19,G19)) | J19: =IF(COUNT(E19,H19)=0,"",SUM(E19,H19)) | K19: Before expiry of year 10 | L19: Year 10 | M19: Sourced | N19: - [Excluded from headline total: Recurring / volume-variable] | O19: No
A20: 3 | B20: Trademark | C20: Trademark per class per mark (TM-A online) | D20: 4500 | E20: 4500 | F20: 9000 | I20: =IF(COUNT(D20,G20)=0,"",SUM(D20,G20)) | J20: =IF(COUNT(E20,H20)=0,"",SUM(E20,H20)) | K20: 6-18 months uncontested | L20: - | M20: Sourced | N20: 12-36 months if objected or opposed. Attorney fee NOT SOURCED. | O20: Yes
A21: 3 | B21: Trademark | C21: MODULARK in Classes 9, 11 and 42 | D21: 13500 | E21: 13500 | F21: 27000 | I21: =IF(COUNT(D21,G21)=0,"",SUM(D21,G21)) | J21: =IF(COUNT(E21,H21)=0,"",SUM(E21,H21)) | K21: Exam reply ~30 days | L21: TM-O opposition window 4 months | M21: Sourced | N21: Class 11 lighting, Class 9 electronics/sensors/batteries, Class 42 SaaS. A TM filing does not disclose the product - safe to run in parallel. | O21: Yes
A22: 3 | B22: Trademark | C22: Objection response / opposition | I22: =IF(COUNT(D22,G22)=0,"",SUM(D22,G22)) | J22: =IF(COUNT(E22,H22)=0,"",SUM(E22,H22)) | K22: Years if opposed | L22: - | M22: NOT SOURCED | N22: An opposed application can run to lakhs. | O22: Yes
A23: 3 | B23: BIS | C23: BIS CRS, per registered model | D23: 15000 | E23: 25000 | I23: =IF(COUNT(D23,G23)=0,"",SUM(D23,G23)) | J23: =IF(COUNT(E23,H23)=0,"",SUM(E23,H23)) | K23: Nominal 20-25 working days; realistic 45-60 | L23: Before placing on market | M23: Sourced | N23: Rs 15,000 inclusion fee includes one test; Rs 10,000 per additional test report; testing Rs 10,000-30,000. Plan 3 months from design freeze. | O23: Yes
A24: 3 | B24: BIS | C24: BIS CRS all-in per article | D24: 30000 | E24: 50000 | I24: =IF(COUNT(D24,G24)=0,"",SUM(D24,G24)) | J24: =IF(COUNT(E24,H24)=0,"",SUM(E24,H24)) | K24: Validity 2 years | L24: - | M24: Sourced | N24: Rs 30,000-35,000 single product one test report; Rs 50,000+ complex. [Excluded from headline total: Roll-up of rows already counted — would double count] | O24: No
A25: 3 | B25: BIS | C25: BIS CRS renewal | D25: 25000 | E25: 25000 | I25: =IF(COUNT(D25,G25)=0,"",SUM(D25,G25)) | J25: =IF(COUNT(E25,H25)=0,"",SUM(E25,H25)) | K25: Apply >=3 months before expiry | L25: Every 2 years | M25: Sourced | N25: - [Excluded from headline total: Recurring / volume-variable] | O25: No
A26: 3 | B26: BIS | C26: Series mechanism - THE COST LEVER | I26: =IF(COUNT(D26,G26)=0,"",SUM(D26,G26)) | J26: =IF(COUNT(E26,H26)=0,"",SUM(E26,H26)) | K26: - | L26: Design decision, not a filing | M26: Sourced | N26: Up to 10 models per registration (50 for fixed general-purpose fancy lights). Design the product family so variants are models within ONE series. [Excluded from headline total: Design decision, not a filing] | O26: No
A27: 3 | B27: Radio | C27: WPC ETA-SD, per model | D27: 10000 | E27: 10000 | F27: 10000 | I27: =IF(COUNT(D27,G27)=0,"",SUM(D27,G27)) | J27: =IF(COUNT(E27,H27)=0,"",SUM(E27,H27)) | K27: 1-7 working days | L27: Before import or sale | M27: Sourced | N27: Via Bharatkosh. No renewal under current 2026 guidance. Radio equipment imported without WPC permission is CONFISCATED at port. | O27: Yes
A28: 3 | B28: Radio | C28: TEC MTCTE | I28: =IF(COUNT(D28,G28)=0,"",SUM(D28,G28)) | J28: =IF(COUNT(E28,H28)=0,"",SUM(E28,H28)) | K28: - | L28: - | M28: Sourced | N28: Assessed as NOT APPLICABLE (endpoint, not gateway/CPE). Verify against the current phase list. | O28: Yes
A29: 3 | B29: EPR | C29: E-waste EPR registration | D29: 10000 | E29: 10000 | F29: 10000 | I29: =IF(COUNT(D29,G29)=0,"",SUM(D29,G29)) | J29: =IF(COUNT(E29,H29)=0,"",SUM(E29,H29)) | K29: Annually renewable | L29: Before placing on market | M29: Sourced | N29: Rs 10,000 flat for a new producer. No turnover or volume exemption exists - the obligation attaches on the first unit sold. | O29: Yes
A30: 3 | B30: EPR | C30: E-waste EPR certificates | I30: =IF(COUNT(D30,G30)=0,"",SUM(D30,G30)) | J30: =IF(COUNT(E30,H30)=0,"",SUM(E30,H30)) | K30: Quarterly + annual returns | L30: Ongoing | M30: CONFLICT | N30: Rs 22-74/kg band for consumer electronics under CPCB 2024 guidelines. Band is under Delhi HC challenge, no final judgment as of mid-2026. Budget at the floor. New producer target: Schedule IV, 20% of sales two FYs prior. [Excluded from headline total: Recurring / volume-variable] | O30: No
A31: 3 | B31: EPR | C31: Battery EPR registration | D31: 2500 | E31: 2500 | F31: 2500 | I31: =IF(COUNT(D31,G31)=0,"",SUM(D31,G31)) | J31: =IF(COUNT(E31,H31)=0,"",SUM(E31,H31)) | K31: Annual Form 1C | L31: Before placing on market | M31: CONFLICT | N31: Rs 2,500 from a single commercial source - indicative only. SEPARATE regime, separate portal, separate calendar. Selling spare swap packs makes this unavoidable. | O31: Yes
A32: 3 | B32: Metrology | C32: Legal Metrology Rule 27 registration | D32: 500 | E32: 500 | F32: 500 | I32: =IF(COUNT(D32,G32)=0,"",SUM(D32,G32)) | J32: =IF(COUNT(E32,H32)=0,"",SUM(E32,H32)) | K32: Within 90 days of pre-packing | L32: Commencement + 90 days | M32: Sourced | N32: Fine for late registration is trivial (Rs 4,000) but non-standard packages are Rs 25,000-1,00,000 per offence. | O32: Yes
A33: 1 | B33: Corporate | C33: MOA objects alteration (MGT-14 + stamp duty) | D33: 300 | E33: 600 | F33: 600 | G33: 8000 | H33: 35000 | I33: =IF(COUNT(D33,G33)=0,"",SUM(D33,G33)) | J33: =IF(COUNT(E33,H33)=0,"",SUM(E33,H33)) | K33: 2-3 weeks shorter notice; 5-6 on full | L33: MGT-14 within 30 days of resolution | M33: Sourced | N33: Stamp duty nil to ~Rs 1,000 in most states for an objects-only change - state-specific, confirm with your CS. Doubled fee if MGT-14 is late. | O33: Yes
A34: 1 | B34: Corporate | C34: MOA alteration all-in | G34: 15000 | H34: 50000 | I34: =IF(COUNT(D34,G34)=0,"",SUM(D34,G34)) | J34: =IF(COUNT(E34,H34)=0,"",SUM(E34,H34)) | K34: - | L34: - | M34: Sourced | N34: Central estimate Rs 20,000-25,000. [Excluded from headline total: Roll-up of rows already counted — would double count] | O34: No
A35: 1 | B35: Corporate | C35: Incorporating the hardware company (SPICe+) | G35: 8000 | H35: 25000 | I35: =IF(COUNT(D35,G35)=0,"",SUM(D35,G35)) | J35: =IF(COUNT(E35,H35)=0,"",SUM(E35,H35)) | K35: Days to weeks | L35: Before first customer-facing activity | M35: Sourced | N35: Incorporate with a manufacturing objects clause and NIC code from the start. | O35: Yes
A36: 3 | B36: Corporate | C36: Carrying an inactive second company | G36: 40000 | H36: 75000 | I36: =IF(COUNT(D36,G36)=0,"",SUM(D36,G36)) | J36: =IF(COUNT(E36,H36)=0,"",SUM(E36,H36)) | K36: Annual | L36: Ongoing | M36: CONFLICT | N36: Rs 40,000-75,000 p.a. pre-revenue; Rs 1,00,000-2,00,000 p.a. once operating with GST. Market estimates, not sourced. [Excluded from headline total: Recurring annual, not a one-off filing] | O36: No
A37: 3 | B37: Corporate | C37: Stamp duty on IP assignment deed | I37: =IF(COUNT(D37,G37)=0,"",SUM(D37,G37)) | J37: =IF(COUNT(E37,H37)=0,"",SUM(E37,H37)) | K37: - | L37: On any transfer | M37: Sourced | N37: 0.5%-5% of consideration, state-specific. | O37: Yes
A38: 3 | B38: Corporate | C38: NCLT demerger (the expensive late alternative) | G38: 1000000 | H38: 3000000 | I38: =IF(COUNT(D38,G38)=0,"",SUM(D38,G38)) | J38: =IF(COUNT(E38,H38)=0,"",SUM(E38,H38)) | K38: 9-18 months | L38: Avoid by structuring now | M38: NOT SOURCED | N38: Market estimate. This is what splitting later costs. The cheapest time to split is before there is anything to split. [Excluded from headline total: Avoidable — this is the cost of NOT structuring now] | O38: No
A39: 3 | B39: Other | C39: Product liability insurance | I39: =IF(COUNT(D39,G39)=0,"",SUM(D39,G39)) | J39: =IF(COUNT(E39,H39)=0,"",SUM(E39,H39)) | K39: Quote before design freeze | L39: Before first sale | M39: NOT SOURCED | N39: No Indian premium figure for a lithium-battery electronics SME could be obtained and none is stated. Lithium exclusions are common. RECALL COST IS EXCLUDED from standard Indian policies. | O39: Yes
A40: 3 | B40: Other | C40: Indian injection mould tooling | I40: =IF(COUNT(D40,G40)=0,"",SUM(D40,G40)) | J40: =IF(COUNT(E40,H40)=0,"",SUM(E40,H40)) | K40: - | L40: If 3D printing fails certification | M40: NOT SOURCED | N40: - | O40: Yes
...

Sheet Budget Summary
A1: Budget Summary by Category
A2: Calculated from the Cost and Timeline tab. Sourced rows only — see Read Me.
A4: Category | B4: Est. total low | C4: Est. total high | D4: Line items
A5: Patent | B5: =SUMIFS('Cost and Timeline'!$I$2:$I$42,'Cost and Timeline'!$B$2:$B$42,$A5,'Cost and Timeline'!$O$2:$O$42,"Yes") | C5: =SUMIFS('Cost and Timeline'!$J$2:$J$42,'Cost and Timeline'!$B$2:$B$42,$A5,'Cost and Timeline'!$O$2:$O$42,"Yes") | D5: =COUNTIF('Cost and Timeline'!$B$2:$B$42,$A5)
A6: Design | B6: =SUMIFS('Cost and Timeline'!$I$2:$I$42,'Cost and Timeline'!$B$2:$B$42,$A6,'Cost and Timeline'!$O$2:$O$42,"Yes") | C6: =SUMIFS('Cost and Timeline'!$J$2:$J$42,'Cost and Timeline'!$B$2:$B$42,$A6,'Cost and Timeline'!$O$2:$O$42,"Yes") | D6: =COUNTIF('Cost and Timeline'!$B$2:$B$42,$A6)
A7: Trademark | B7: =SUMIFS('Cost and Timeline'!$I$2:$I$42,'Cost and Timeline'!$B$2:$B$42,$A7,'Cost and Timeline'!$O$2:$O$42,"Yes") | C7: =SUMIFS('Cost and Timeline'!$J$2:$J$42,'Cost and Timeline'!$B$2:$B$42,$A7,'Cost and Timeline'!$O$2:$O$42,"Yes") | D7: =COUNTIF('Cost and Timeline'!$B$2:$B$42,$A7)
A8: BIS | B8: =SUMIFS('Cost and Timeline'!$I$2:$I$42,'Cost and Timeline'!$B$2:$B$42,$A8,'Cost and Timeline'!$O$2:$O$42,"Yes") | C8: =SUMIFS('Cost and Timeline'!$J$2:$J$42,'Cost and Timeline'!$B$2:$B$42,$A8,'Cost and Timeline'!$O$2:$O$42,"Yes") | D8: =COUNTIF('Cost and Timeline'!$B$2:$B$42,$A8)
A9: Radio | B9: =SUMIFS('Cost and Timeline'!$I$2:$I$42,'Cost and Timeline'!$B$2:$B$42,$A9,'Cost and Timeline'!$O$2:$O$42,"Yes") | C9: =SUMIFS('Cost and Timeline'!$J$2:$J$42,'Cost and Timeline'!$B$2:$B$42,$A9,'Cost and Timeline'!$O$2:$O$42,"Yes") | D9: =COUNTIF('Cost and Timeline'!$B$2:$B$42,$A9)
A10: EPR | B10: =SUMIFS('Cost and Timeline'!$I$2:$I$42,'Cost and Timeline'!$B$2:$B$42,$A10,'Cost and Timeline'!$O$2:$O$42,"Yes") | C10: =SUMIFS('Cost and Timeline'!$J$2:$J$42,'Cost and Timeline'!$B$2:$B$42,$A10,'Cost and Timeline'!$O$2:$O$42,"Yes") | D10: =COUNTIF('Cost and Timeline'!$B$2:$B$42,$A10)
A11: Metrology | B11: =SUMIFS('Cost and Timeline'!$I$2:$I$42,'Cost and Timeline'!$B$2:$B$42,$A11,'Cost and Timeline'!$O$2:$O$42,"Yes") | C11: =SUMIFS('Cost and Timeline'!$J$2:$J$42,'Cost and Timeline'!$B$2:$B$42,$A11,'Cost and Timeline'!$O$2:$O$42,"Yes") | D11: =COUNTIF('Cost and Timeline'!$B$2:$B$42,$A11)
A12: Corporate | B12: =SUMIFS('Cost and Timeline'!$I$2:$I$42,'Cost and Timeline'!$B$2:$B$42,$A12,'Cost and Timeline'!$O$2:$O$42,"Yes") | C12: =SUMIFS('Cost and Timeline'!$J$2:$J$42,'Cost and Timeline'!$B$2:$B$42,$A12,'Cost and Timeline'!$O$2:$O$42,"Yes") | D12: =COUNTIF('Cost and Timeline'!$B$2:$B$42,$A12)
A13: Other | B13: =SUMIFS('Cost and Timeline'!$I$2:$I$42,'Cost and Timeline'!$B$2:$B$42,$A13,'Cost and Timeline'!$O$2:$O$42,"Yes") | C13: =SUMIFS('Cost and Timeline'!$J$2:$J$42,'Cost and Timeline'!$B$2:$B$42,$A13,'Cost and Timeline'!$O$2:$O$42,"Yes") | D13: =COUNTIF('Cost and Timeline'!$B$2:$B$42,$A13)
A14: TOTAL | B14: =SUM(B5:B13) | C14: =SUM(C5:C13)
A16: Reality check: the first twelve months, done properly — DPIIT recognition, prior art search, one design filing, one thick provisional, MOA alteration, three trademark classes — is realistically Rs 1.5-3 lakh. Certification and EPR land later and are a separate, larger bill.

Sheet Hard Deadlines
A1: Hard Deadlines — missing these destroys rights
A2: Read this tab before anything else. Several of these cannot be cured at any price.
A4: Deadline | B4: What is due | C4: Consequence of missing it | D4: Severity
A5: Provisional + 6 weeks (or Form 25 FFL) | B5: Section 39 clearance before ANY foreign filing | C5: CRIMINAL OFFENCE under s.118 - up to 2 years imprisonment. Application deemed abandoned (s.40). Patent revocable (s.64). Liability can extend beyond the named inventor to whoever authorised the filing. | D5: CRIMINAL
A6: Provisional + 12 months | B6: Complete specification | C6: ABSOLUTE. No extension, no condonation, no post-dating. Application abandoned, priority lost. | D6: FATAL
A7: Provisional + 12 months | B7: PCT / Paris Convention patent filings | C7: All foreign patent rights lost permanently. | D7: FATAL
A8: Before any public disclosure | B8: Design application AND patent provisional on file | C8: India is an absolute-novelty jurisdiction. s.31 is exhibition-and-Gazette-tied, not a general grace period, and since 15 Mar 2024 is not self-executing (Rule 29A / Form 31). Designs have NO general grace period at all. | D8: FATAL
A9: Provisional + 6 months | B9: Proof of right on file (Rule 138: max 1 month extension, requested within the six) | C9: Objection raised. Whether a late or defective proof of right is curable is UNKNOWN - unresolved Madras HC point. | D9: HIGH
A10: Provisional + 6 months | B10: Paris Convention design priority window if filing abroad | C10: Foreign design rights lost. | D10: HIGH
A11: Before unit no. 51 exists | B11: Design registration on file | C11: Copyright Act s.15(2) extinguishes your fallback copyright after 50 industrial reproductions. | D11: HIGH
A12: Earliest priority + 31 months | B12: RFE (Form 18) AND PCT national phase - SAME DATE now | C12: Application deemed withdrawn. The 2024 Rules merged these; docket as one date. | D12: FATAL
A13: Within 30 days of the resolution | B13: MGT-14 for the objects alteration | C13: Doubled fee up to 30 days, escalating thereafter. | D13: MEDIUM
A14: Within 90 days of commencing pre-packing | B14: Legal Metrology Rule 27 registration | C14: Rs 4,000 fine is trivial - but non-standard packages are Rs 25,000-1,00,000 PER OFFENCE. | D14: MEDIUM
A15: 1 October 2026 — CHECK THIS WEEK | B15: Appliances QCO 2026 comes into force | C15: Product list was not readable from this environment. Possible Scheme I ISI obligation. Verify immediately. | D15: URGENT - VERIFY
... A18: ~May 2027 (13 or 14 - verify) | B18: DPDP Act substantive obligations commence | C18: Book one day of counsel in Q1 2027. Not in force before then and the Board has no members appointed. | D18: MEDIUM

Sheet Action Plan
A1: Priority-Ordered Action Plan
A2: Sequencing matters more than speed. Phase 0 items destroy rights permanently if done out of order.
A3: Owner, Target date and Status are for you to fill in.
A5: # | B5: Phase | C5: Action | D5: Why it is in this position | E5: Owner | F5: Target date | G5: Status
A6: 1 | B6: 0 — Before anything leaves the building | C6: Stop all external disclosure now | D6: No photos, renders, demos, decks with product imagery, public repo, press, crowdfunding or trade show. Every day of exposure is irreversible.
A7: 2 | B7: 0 | C7: Get DPIIT Startup recognition and/or Udyam MSME registration | D7: Free. Roughly halves every patent, design and trademark official fee. Must be IN HAND at filing - Form 28 for patents, Form 24 for designs.
A8: 3 | B8: 0 | C8: Read your filed MOA from MCA21 | D8: Answer whether it authorises manufacture. View Public Documents on mca.gov.in.
A9: 4 | B9: 0 | C9: Commission the professional prior art / FTO search | D9: CPC H05B47/105, /11, /115, /155, /165, /19 and G05B13/*, plus battery contact geometry and dead-until-mated. Gates BOTH the sweep filing scope and the ring-contact go/no-go. Do it before paying for a complete specification.
A10: 5 | B10: 0 | C10: Answer: do school fee payments ever settle into a Modulark account, even briefly? | D10: If yes, that is unauthorised payment aggregation. The authorisation threshold is Rs 15 crore net worth. Fix the fund flow immediately.
A11: 6 | B11: 0 | C11: Incorporate the hardware company via SPICe+ | D11: With a manufacturing objects clause and NIC code from the start.
A12: 7 | B12: 0 | C12: Put employment / contractor / CM IP clauses in place | D12: Present-tense assignment, further assurances, POA, enumerated confidentiality, designer portfolio prohibition. BEFORE the next person touches the design. Patent rights need EXPRESS assignment - unlike copyright they do not vest automatically.
A13: 8 | B13: 1 — File | C13: Freeze the industrial design | D13: -
A14: 9 | B14: 1 | C14: File the Indian design application(s) in Locarno 26-05 | D14: Assembled module, light head and wall disc as separate designs. Detail-specific statement of novelty. Form 24 plus DPIIT/Udyam certificate. FILE INDIA FIRST.
A15: 10 | B15: 1 | C15: File the patent provisional, same day or immediately after | D15: Applicant = the hardware company. Proof of right via Form 1 declaration or pre-dated assignment deed. Make it THICK: sensing node construction, sweep procedure with settling times, daylight estimation, constraint set, wireless path, real numbers, every variant you may ever claim.
A16: 11 | B16: 1 | C16: Get the application numbers in hand | D16: Only now does Phase 2 open. This is the gate.
A17: 12 | B17: 3 — Long lead times | C17: Amend the objects clause | D17: 2-3 weeks on shorter notice. Run in parallel with Phase 1.
... A26: 21 | B26: 3 | C26: E-waste EPR and Battery EPR registrations | D26: Two portals, two calendars. Before placing product on the market. No small-producer exemption exists.
